<mujoco model="layer1">
    <compiler angle="degree" meshdir="./assets">
        <lengthrange mode="muscle" uselimit="true"/>
    </compiler>
    <asset>
        <material name="metal" rgba="0.58 0.58 0.58 1"/>
        <material name="silicone" rgba="0.1882 0.1882 0.1882 1"/>
        <material name="gray" rgba="0.4627 0.4627 0.4627 1"/>
        <material name="black" rgba="0.149 0.149 0.149 1"/>
        <material name="translucent_white_plastic" rgba="0.9 0.9 0.9 0.7" specular="0.8" shininess="0.6"/>
        <material name="matte_white_plastic" rgba="0.85 0.85 0.85 0.8" specular="0.2" shininess="0.1"/>
        <material name="acrylic_white_plastic" rgba="0.95 0.95 0.95 0.6" specular="0.9" shininess="0.9"/>
        <material name="clear_tube_plastic" rgba="1 1 1 0.35" specular="0.9" shininess="0.8" reflectance="0.2"/>
        <material name="matte_black_plastic" rgba="0.15 0.15 0.15 1" specular="0.1" shininess="0.1"/>
        <material name="polished_silver" rgba="0.8 0.8 0.8 1" specular="0.9" shininess="0.9"/>
        <mesh class="str" file="Cap.stl" />
        <mesh class="str" file="Mujoco_end.stl" />
        <mesh class="str" file="Mujoco_Fix_Ring.stl" />
        <model name="layer2" file="section_module_2.xml"/>
    </asset>
    <default>
        <default class="hingeB">
            <joint stiffness="0.0755" damping="7" armature="0.005"/>
        </default>
        <default class="interZ">
            <joint type="slide" stiffness='5870' ref="-0.00120" armature="0.012" damping="7" frictionloss="0.2" />
        </default>
        <default class="secZ">
            <joint type="slide" stiffness='5870' ref="-0.00120" armature="0.035" damping="11" frictionloss="0.2"/>
        </default>
        <default class="str">
            <mesh scale="0.001 0.001 0.001"/>
            <general biastype="affine"/>
        </default>
        <default class="vis">
            <geom contype="0" conaffinity="0" density="0" group="0"/>
        </default>
        <default class="col">
            <geom contype="1" conaffinity="1" group="3" rgba="0.9 0.2 0.2 0.25"/>
        </default>
    </default>
    <worldbody>
        <body name='layer_core'>
            <inertial pos="0.00 0.00 -0.047" quat="1 0 0 0" mass="0.452" diaginertia="6.975e-4 6.975e-4 5.153e-4"/>
            <geom class="vis" type="mesh" mesh="Mujoco_end" pos="0 0 0" euler= '180 0 0 ' material = 'matte_black_plastic'/>
            <geom class="col" name="Mujoco_end_col_1" type="cylinder" size="0.0225 0.0451" pos="0 0.03 -0.0451"/>
            <geom class="col" name="Mujoco_end_col_2" type="cylinder" size="0.0225 0.0451" pos="0.025981 -0.015 -0.0451"/>
            <geom class="col" name="Mujoco_end_col_3" type="cylinder" size="0.0225 0.0451" pos="-0.025981 -0.015 -0.0451"/>
            <site name= "imu_site_01" pos="0 0.03 -0.0402 "/>
            <site name= "imu_site_02" pos="0.025981 -0.015 -0.0402 "/>
            <site name= "imu_site_03" pos="-0.025981 -0.015 -0.0402 "/>
            <site name="layer01" pos="0 0.03 -0.0902 "/>
            <site name="layer11" pos="0.025981 -0.015 -0.0902 "/>
            <site name="layer21" pos="-0.025981 -0.015 -0.0902 "/>
            <body name='sec_1' pos= '0 0 -0.1386' euler='180 0 0'>
                <inertial pos="0.00 0.00 0.0025" quat="1 0 0 0" mass="0.012" diaginertia="4.867e-6 4.867e-6 9.673e-6"/>
                <geom class="vis" type="mesh" mesh="Mujoco_Fix_Ring" pos="0 0 0" material = 'matte_black_plastic'/>
                <geom class="col" name="Mujoco_Fix_Ring_col_1_1" type="cylinder" size="0.02 0.0025" pos="0 -0.03 0.0025 "/>
                <geom class="col" name="Mujoco_Fix_Ring_col_1_2" type="cylinder" size="0.02 0.0025" pos="0.025981 0.015 0.0025 "/>
                <geom class="col" name="Mujoco_Fix_Ring_col_1_3" type="cylinder" size="0.02 0.0025" pos="-0.025981 0.015 0.0025 "/>
                <geom class="col" name="Mujoco_Fix_Ring_col_1_4" type="cylinder" size="0.01 0.0025" pos="0 0 0.0025 "/>
                <joint name="sec_1_joint_x" class="hingeB" type="hinge" axis="1 0 0" pos="0 0 -0.0242  " limited="true" range="-50 50"/>
                <joint name="sec_1_joint_y" class="hingeB" type="hinge" axis="0 1 0" pos="0 0 -0.0242  " limited="true" range="-50 50"/>
                <joint name="sec_1_joint_z" class='secZ' type="slide" axis="0 0 1" pos="0 0 -0.0242  " limited="true" range="-0.023 0.001" />
                <site name="layer02" pos="0 -0.03 0.005 "/>
                <site name="layer12" pos="0.025981 0.015 0.005 "/>
                <site name="layer22" pos="-0.025981 0.015 0.005 "/>
                <body name='sec_2' pos= '0 0 0.0484' euler='0 0 0'>
                    <inertial pos="0.00 0.00 0.0025" quat="1 0 0 0" mass="0.012" diaginertia="4.867e-6 4.867e-6 9.673e-6"/>
                    <geom class="vis" type="mesh" mesh="Mujoco_Fix_Ring" pos="0 0 0" material = 'matte_black_plastic'/>
                    <geom class="col" name="Mujoco_Fix_Ring_col_2_1" type="cylinder" size="0.02 0.0025" pos="0 -0.03 0.0025 "/>
                    <geom class="col" name="Mujoco_Fix_Ring_col_2_2" type="cylinder" size="0.02 0.0025" pos="0.025981 0.015 0.0025 "/>
                    <geom class="col" name="Mujoco_Fix_Ring_col_2_3" type="cylinder" size="0.02 0.0025" pos="-0.025981 0.015 0.0025 "/>
                    <geom class="col" name="Mujoco_Fix_Ring_col_2_4" type="cylinder" size="0.01 0.0025" pos="0 0 0.0025 "/>
                    <joint name="sec_2_joint_x" class="hingeB" type="hinge" axis="1 0 0" pos="0 0 -0.0242  " limited="true" range="-50 50"/>
                    <joint name="sec_2_joint_y" class="hingeB" type="hinge" axis="0 1 0" pos="0 0 -0.0242  " limited="true" range="-50 50"/>
                    <joint name="sec_2_joint_z" class='secZ' type="slide" axis="0 0 1" pos="0 0 -0.0242  " limited="true" range="-0.023 0.001" />
                    <site name="layer03" pos="0 -0.03 0.005 "/>
                    <site name="layer13" pos="0.025981 0.015 0.005 "/>
                    <site name="layer23" pos="-0.025981 0.015 0.005 "/>
                    <body name='sec_3' pos= '0 0 0.0484' euler='0 0 0'>
                        <inertial pos="0.00 0.00 0.0025" quat="1 0 0 0" mass="0.012" diaginertia="4.867e-6 4.867e-6 9.673e-6"/>
                        <geom class="vis" type="mesh" mesh="Mujoco_Fix_Ring" pos="0 0 0" material = 'matte_black_plastic'/>
                        <geom class="col" name="Mujoco_Fix_Ring_col_3_1" type="cylinder" size="0.02 0.0025" pos="0 -0.03 0.0025 "/>
                        <geom class="col" name="Mujoco_Fix_Ring_col_3_2" type="cylinder" size="0.02 0.0025" pos="0.025981 0.015 0.0025 "/>
                        <geom class="col" name="Mujoco_Fix_Ring_col_3_3" type="cylinder" size="0.02 0.0025" pos="-0.025981 0.015 0.0025 "/>
                        <geom class="col" name="Mujoco_Fix_Ring_col_3_4" type="cylinder" size="0.01 0.0025" pos="0 0 0.0025 "/>
                        <joint name="sec_3_joint_x" class="hingeB" type="hinge" axis="1 0 0" pos="0 0 -0.0242  " limited="true" range="-50 50"/>
                        <joint name="sec_3_joint_y" class="hingeB" type="hinge" axis="0 1 0" pos="0 0 -0.0242  " limited="true" range="-50 50"/>
                        <joint name="sec_3_joint_z" class='secZ' type="slide" axis="0 0 1" pos="0 0 -0.0242  " limited="true" range="-0.023 0.001" />
                        <site name="layer04" pos="0 -0.03 0.005 "/>
                        <site name="layer14" pos="0.025981 0.015 0.005 "/>
                        <site name="layer24" pos="-0.025981 0.015 0.005 "/>

                        <body name='sec_4' pos= '0 0 0.0484' euler='0 0 0'>
                            <inertial pos="0.00 0.00 0.0025" quat="1 0 0 0" mass="0.012" diaginertia="4.867e-6 4.867e-6 9.673e-6"/>
                            <geom class="vis" type="mesh" mesh="Mujoco_Fix_Ring" pos="0 0 0" material = 'matte_black_plastic'/>
                            <geom class="col" name="Mujoco_Fix_Ring_col_4_1" type="cylinder" size="0.02 0.0025" pos="0 -0.03 0.0025 "/>
                            <geom class="col" name="Mujoco_Fix_Ring_col_4_2" type="cylinder" size="0.02 0.0025" pos="0.025981 0.015 0.0025 "/>
                            <geom class="col" name="Mujoco_Fix_Ring_col_4_3" type="cylinder" size="0.02 0.0025" pos="-0.025981 0.015 0.0025 "/>
                            <geom class="col" name="Mujoco_Fix_Ring_col_4_4" type="cylinder" size="0.01 0.0025" pos="0 0 0.0025 "/>
                            <joint name="sec_4_joint_x" class="hingeB" type="hinge" axis="1 0 0" pos="0 0 -0.0242  " limited="true" range="-50 50"/>
                            <joint name="sec_4_joint_y" class="hingeB" type="hinge" axis="0 1 0" pos="0 0 -0.0242  " limited="true" range="-50 50"/>
                            <joint name="sec_4_joint_z" class='secZ' type="slide" axis="0 0 1" pos="0 0 -0.0242  " limited="true" range="-0.023 0.001" />
                            <site name="layer05" pos="0 -0.03 0.005 "/>
                            <site name="layer15" pos="0.025981 0.015 0.005 "/>
                            <site name="layer25" pos="-0.025981 0.015 0.005 "/>

                            <body name='sec_5' pos= '0 0 0.0484' euler='0 0 0'>
                                <inertial pos="0.00 0.00 0.0025" quat="1 0 0 0" mass="0.012" diaginertia="4.867e-6 4.867e-6 9.673e-6"/>
                                <geom class="vis" type="mesh" mesh="Mujoco_Fix_Ring" pos="0 0 0" material = 'matte_black_plastic'/>
                                <geom class="col" name="Mujoco_Fix_Ring_col_5_1" type="cylinder" size="0.02 0.0025" pos="0 -0.03 0.0025 "/>
                                <geom class="col" name="Mujoco_Fix_Ring_col_5_2" type="cylinder" size="0.02 0.0025" pos="0.025981 0.015 0.0025 "/>
                                <geom class="col" name="Mujoco_Fix_Ring_col_5_3" type="cylinder" size="0.02 0.0025" pos="-0.025981 0.015 0.0025 "/>
                                <geom class="col" name="Mujoco_Fix_Ring_col_5_4" type="cylinder" size="0.01 0.0025" pos="0 0 0.0025 "/>
                                <joint name="sec_5_joint_x" class="hingeB" type="hinge" axis="1 0 0" pos="0 0 -0.0242" limited="true" range="-50 50"/>
                                <joint name="sec_5_joint_y" class="hingeB" type="hinge" axis="0 1 0" pos="0 0 -0.0242" limited="true" range="-50 50"/>
                                <joint name="sec_5_joint_z" class='secZ' type="slide" axis="0 0 1" pos="0 0 -0.0242" limited="true" range="-0.023 0.001" />
                                <site name="layer06" pos="0 -0.03 0.005 "/>
                                <site name="layer16" pos="0.025981 0.015 0.005 "/>
                                <site name="layer26" pos="-0.025981 0.015 0.005 "/>

                                <body name='sec_6' pos= '0 0 0.0484' euler='0 0 0'>
                                    <inertial pos="0.00 0.00 0.0045" quat="1 0 0 0" mass="0.036" diaginertia="2.092e-6 2.092e-6 4.135e-6"/>
                                    <geom class="vis" type="mesh" mesh="Cap" pos="0 0 0"  material = 'matte_black_plastic'/>
                                    <geom class="col" name="Cap_1" type="cylinder" size="0.02 0.004" pos="0 -0.03 0.004 "/>
                                    <geom class="col" name="Cap_2" type="cylinder" size="0.02 0.004" pos="0.025981 0.015 0.004 "/>
                                    <geom class="col" name="Cap_3" type="cylinder" size="0.02 0.004" pos="-0.025981 0.015 0.004 "/>
                                    <joint name="sec_6_joint_x" class="hingeB" type="hinge" axis="1 0 0" pos="0 0 -0.0242  " limited="true" range="-50 50"/>
                                    <joint name="sec_6_joint_y" class="hingeB" type="hinge" axis="0 1 0" pos="0 0 -0.0242  " limited="true" range="-50 50"/>
                                    <joint name="sec_6_joint_z" class='secZ' type="slide" axis="0 0 1" pos="0 0 -0.0242  " limited="true" range="-0.010 0.001" />
                                    <site name="layer07" pos="0 -0.03 0 "/>
                                    <site name="layer17" pos="0.025981 0.015 0 "/>
                                    <site name="layer27" pos="-0.025981 0.015 0 "/>
                                    <body name="mount" pos= '0 0 0.008' euler='180 0 0 '>
                                        <attach model="layer2" body="layer_core" prefix="L"/>
                                    </body>
                                </body>
                            </body>
                        </body>
                    </body>
                </body>
            </body>
        </body>
    </worldbody>
    <tendon >
        <spatial name="layer00" range=".15 .33" limited="true" width=".015" rgba="0.55 0.55 0.55 1" stiffness='128' damping= '2'>
            <site site="layer01"/>
            <site site="layer02"/>
            <site site="layer03"/>
            <site site="layer04"/>
            <site site="layer05"/>
            <site site="layer06"/>
            <site site="layer07"/>
        </spatial>
        <spatial name="layer01" range=".15 .33" limited="true" width=".015" rgba="0.55 0.55 0.55 1" stiffness='128' damping= '2'>
            <site site="layer11"/>
            <site site="layer12"/>
            <site site="layer13"/>
            <site site="layer14"/>
            <site site="layer15"/>
            <site site="layer16"/>
            <site site="layer17"/>
        </spatial>
        <spatial name="layer02" range=".15 .33" limited="true" width=".015" rgba="0.55 0.55 0.55 1" stiffness='128' damping= '2'>
            <site site="layer21"/>
            <site site="layer22"/>
            <site site="layer23"/>
            <site site="layer24"/>
            <site site="layer25"/>
            <site site="layer26"/>
            <site site="layer27"/>
        </spatial>
    </tendon>
    <contact>
    <!-- 仅举例：依次禁掉相邻段之间的碰撞（x/y/z 全部几何都不再互撞） -->
    <exclude body1="sec_1" body2="sec_2"/>
    <exclude body1="sec_2" body2="sec_3"/>
    <exclude body1="sec_3" body2="sec_4"/>
    <exclude body1="sec_4" body2="sec_5"/>
    <exclude body1="sec_5" body2="sec_6"/>
    </contact>
    <equality>
        <joint joint1="sec_1_joint_x" joint2="sec_2_joint_x" polycoef="0 1 0 0 0"/>
        <joint joint1="sec_1_joint_y" joint2="sec_2_joint_y" polycoef="0 1 0 0 0"/>
        <joint joint1="sec_2_joint_x" joint2="sec_3_joint_x" polycoef="0 1 0 0 0"/>
        <joint joint1="sec_2_joint_y" joint2="sec_3_joint_y" polycoef="0 1 0 0 0"/>
        <joint joint1="sec_3_joint_x" joint2="sec_4_joint_x" polycoef="0 1 0 0 0"/>
        <joint joint1="sec_3_joint_y" joint2="sec_4_joint_y" polycoef="0 1 0 0 0"/>
        <joint joint1="sec_4_joint_x" joint2="sec_5_joint_x" polycoef="0 1 0 0 0"/>
        <joint joint1="sec_4_joint_y" joint2="sec_5_joint_y" polycoef="0 1 0 0 0"/>
        <joint joint1="sec_5_joint_x" joint2="sec_6_joint_x" polycoef="0 1 0 0 0"/>
        <joint joint1="sec_5_joint_y" joint2="sec_6_joint_y" polycoef="0 1 0 0 0"/>
    </equality>
    <sensor>
        <gyro site="imu_site_01"/>
        <accelerometer site="imu_site_01"/>
        <gyro site="imu_site_02"/>
        <accelerometer site="imu_site_02"/>
        <gyro site="imu_site_03"/>
        <accelerometer site="imu_site_03"/>
    </sensor>
</mujoco>
